Workbook

Sheet Res Semanal
A2: semana 1
A3: GRAL | B3: TEMM | C3: CUOTA DIA | D3: alcance | E3: GAP | F3: produc | G3: obj | H3: gap
A4: altas totales | B4: =+'Seg Diario'!M4 -> 0 | C4: =+'Seg Diario'!N4 -> 79.469291 | D4: =+B4/C4 -> 0 | E4: =+B4-C4 -> -79.469291 | F4: =+B4/J4/46 -> 0 | G4: =+C4/J4/J5 -> 0.20534701 | H4: =+F4-G4 -> -0.20534701 | I4: dia | J4: 9
A5: temm | B5: =+'Seg Diario'!Q4 -> 496 | C5: =+'Seg Diario'!R4 -> 39.826684 | D5: =+B5/C5 -> 12.453962 | E5: =+B5-C5 -> 456.17332 | F5: =+B5/J4/J5 -> 1.2816537 | G5: =+C5/J4/J5 -> 0.10291133 | H5: =+F5-G5 -> 1.1787424 | I5: PDV´s | J5: 43
A6: porta | B6: =+'Seg Diario'!U4 -> 0 | C6: =+'Seg Diario'!V4 -> 6.63289 | D6: =+B6/C6 -> 0 | E6: =+B6-C6 -> -6.63289 | F6: =+B6/J4/J5 -> 0 | G6: =+C6/J4/J5 -> 0.017139251 | H6: =+F6-G6 -> -0.017139251
A7: pp voz | B7: =+'Seg Diario'!Y4 -> -496 | C7: =+'Seg Diario'!Z4 -> 33.009717 | D7: =+B7/C7 -> -15.025879 | E7: =+B7-C7 -> -529.00972 | F7: =+B7/J4/J5 -> -1.2816537 | G7: =+C7/J4/J5 -> 0.085296426 | H7: =+F7-G7 -> -1.3669502
A8: semana 2
A9: PALANCA | B9: TEMM | C9: CUOTA DIA | D9: alcance | E9: GAP | F9: produc | G9: obj | H9: gap | I9: PDVS | J9: DIA
A10: MAXI FEST | B10: =SUMIFS('Seg Diario'!Q:Q,'Seg Diario'!D:D,"MAXI FEST") -> 0 | C10: =SUMIFS('Seg Diario'!R:R,'Seg Diario'!D:D,"MAXI FEST") -> 0 | D10: =+B10/C10 -> #DIV/0! | E10: =+B10-C10 -> 0 | F10: =+B10/I10/$J$10 -> 0 | G10: =+C10/I10/$J$10 -> 0 | H10: =+F10-G10 -> 0 | I10: 6 | J10: 9
A11: 10 PDVS | B11: =SUMIFS('Seg Diario'!Q:Q,'Seg Diario'!D:D,"10 TIENDAS EN ENFOQUE") -> 0 | C11: =SUMIFS('Seg Diario'!R:R,'Seg Diario'!D:D,"10 TIENDAS EN ENFOQUE") -> 0 | D11: =+B11/C11 -> #DIV/0! | E11: =+B11-C11 -> 0 | F11: =+B11/I11/$J$10 -> 0 | G11: =+C11/I11/$J$10 -> 0 | H11: =+F11-G11 -> 0 | I11: 10
A12: OPPO | B12: =SUMIFS('Seg Diario'!Q:Q,'Seg Diario'!D:D,"OPPO") -> 0 | C12: =SUMIFS('Seg Diario'!R:R,'Seg Diario'!D:D,"OPPO") -> 0 | D12: =+B12/C12 -> #DIV/0! | E12: =+B12-C12 -> 0 | F12: =+B12/I12/$J$10 -> 0 | G12: =+C12/I12/$J$10 -> 0 | H12: =+F12-G12 -> 0 | I12: 5
A13: MOTOROLA | B13: =SUMIFS('Seg Diario'!Q:Q,'Seg Diario'!D:D,"MOTOROLA") -> 0 | C13: =SUMIFS('Seg Diario'!R:R,'Seg Diario'!D:D,"MOTOROLA") -> 0 | D13: =+B13/C13 -> #DIV/0! | E13: =+B13-C13 -> 0 | F13: =+B13/I13/$J$10 -> 0 | G13: =+C13/I13/$J$10 -> 0 | H13: =+F13-G13 -> 0 | I13: 7
A15: MAXI FEST | B15: altas | C15: cuota | D15: alcance | E15: GAP | F15: produc | G15: obj | H15: gap
A16: altas totales | B16: =+'Seg Diario'!M16 -> 0 | C16: =+'Seg Diario'!N16 -> 2.0482154 | D16: =+B16/C16 -> 0 | E16: =+B16-C16 -> -2.0482154 | F16: =+B16/J16/46 -> 0 | G16: =+C16/J16/J17 -> 0.042671155 | H16: =+F16-G16 -> -0.042671155 | I16: dia | J16: 8
A17: temm | B17: =+'Seg Diario'!Q16 -> 0 | C17: =+'Seg Diario'!R16 -> 0.96380871 | D17: =+B17/C17 -> 0 | E17: =+B17-C17 -> -0.96380871 | F17: =+B17/J16/J17 -> 0 | G17: =+C17/J16/J17 -> 0.020079348 | H17: =+F17-G17 -> -0.020079348 | I17: PDV´s | J17: 6
A18: porta | B18: =+'Seg Diario'!U16 -> 0 | C18: =+'Seg Diario'!V16 -> 0.120598 | D18: =+B18/C18 -> 0 | E18: =+B18-C18 -> -0.120598 | F18: =+B18/J16/J17 -> 0 | G18: =+C18/J16/J17 -> 0.0025124584 | H18: =+F18-G18 -> -0.0025124584
A19: pp voz | B19: =+'Seg Diario'!Y16 -> 0 | C19: =+'Seg Diario'!Z16 -> 0.96380871 | D19: =+B19/C19 -> 0 | E19: =+B19-C19 -> -0.96380871 | F19: =+B19/J16/J17 -> 0 | G19: =+C19/J16/J17 -> 0.020079348 | H19: =+F19-G19 -> -0.020079348
A21: OPPO | B21: altas | C21: cuota | D21: alcance | E21: GAP | F21: produc | G21: obj | H21: gap
A22: altas totales | B22: =+'Seg Diario'!M22 -> 0 | C22: =+'Seg Diario'!N22 -> 1.9105285 | D22: =+B22/C22 -> 0 | E22: =+B22-C22 -> -1.9105285 | F22: =+B22/J22/46 -> 0 | G22: =+C22/J22/J23 -> #DIV/0! | H22: =+F22-G22 -> #DIV/0! | I22: dia | J22: 8
A23: temm | B23: =+'Seg Diario'!Q22 -> 0 | C23: =+'Seg Diario'!R22 -> 1.1014957 | D23: =+B23/C23 -> 0 | E23: =+B23-C23 -> -1.1014957 | F23: =+B23/J22/J23 -> #DIV/0! | G23: =+C23/J22/J23 -> #DIV/0! | H23: =+F23-G23 -> #DIV/0! | I23: PDV´s
A24: porta | B24: =+'Seg Diario'!U22 -> 0 | C24: =+'Seg Diario'!V22 -> 0.120598 | D24: =+B24/C24 -> 0 | E24: =+B24-C24 -> -0.120598 | F24: =+B24/J22/J23 -> #DIV/0! | G24: =+C24/J22/J23 -> #DIV/0! | H24: =+F24-G24 -> #DIV/0!
A25: pp voz | B25: =+'Seg Diario'!Y22 -> 0 | C25: =+'Seg Diario'!Z22 -> 0.68843479 | D25: =+B25/C25 -> 0 | E25: =+B25-C25 -> -0.68843479 | F25: =+B25/J22/J23 -> #DIV/0! | G25: =+C25/J22/J23 -> #DIV/0! | H25: =+F25-G25 -> #DIV/0!
A27: MOTOROLA | B27: altas | C27: cuota | D27: alcance | E27: GAP | F27: produc | G27: obj | H27: gap
A28: altas totales | B28: =+'Seg Diario'!M28 -> 0 | C28: =+'Seg Diario'!N28 -> 4.2341178 | D28: =+B28/C28 -> 0 | E28: =+B28-C28 -> -4.2341178 | F28: =+B28/J28/46 -> 0 | G28: =+C28/J28/J29 -> #DIV/0! | H28: =+F28-G28 -> #DIV/0! | I28: dia | J28: 8
A29: temm | B29: =+'Seg Diario'!Q28 -> 0 | C29: =+'Seg Diario'!R28 -> 2.3235893 | D29: =+B29/C29 -> 0 | E29: =+B29-C29 -> -2.3235893 | F29: =+B29/J28/J29 -> #DIV/0! | G29: =+C29/J28/J29 -> #DIV/0! | H29: =+F29-G29 -> #DIV/0! | I29: PDV´s
A30: porta | B30: =+'Seg Diario'!U28 -> 0 | C30: =+'Seg Diario'!V28 -> 0.241196 | D30: =+B30/C30 -> 0 | E30: =+B30-C30 -> -0.241196 | F30: =+B30/J28/J29 -> #DIV/0! | G30: =+C30/J28/J29 -> #DIV/0! | H30: =+F30-G30 -> #DIV/0!
A31: pp voz | B31: =+'Seg Diario'!Y28 -> 0 | C31: =+'Seg Diario'!Z28 -> 1.6693325 | D31: =+B31/C31 -> 0 | E31: =+B31-C31 -> -1.6693325 | F31: =+B31/J28/J29 -> #DIV/0! | G31: =+C31/J28/J29 -> #DIV/0! | H31: =+F31-G31 -> #DIV/0!
A32: GRAL | B32: TEMM | C32: CUOTA DIA | D32: alcance | E32: GAP | F32: produc | G32: obj | H32: gap
A33: altas totales | B33: =+'Seg Diario'!M33 -> 0 | C33: =+'Seg Diario'!N33 -> 1.7728415 | D33: =+B33/C33 -> 0 | E33: =+B33-C33 -> -1.7728415 | F33: =+B33/J33/46 -> 0 | G33: =+C33/J33/J34 -> 0.0045809858 | H33: =+F33-G33 -> -0.0045809858 | I33: dia | J33: 9
A34: temm | B34: =+'Seg Diario'!Q33 -> 0 | C34: =+'Seg Diario'!R33 -> 0.96380871 | D34: =+B34/C34 -> 0 | E34: =+B34-C34 -> -0.96380871 | F34: =+B34/J33/J34 -> 0 | G34: =+C34/J33/J34 -> 0.0024904618 | H34: =+F34-G34 -> -0.0024904618 | I34: PDV´s | J34: 43
A35: porta | B35: =+'Seg Diario'!U33 -> 0 | C35: =+'Seg Diario'!V33 -> 0.120598 | D35: =+B35/C35 -> 0 | E35: =+B35-C35 -> -0.120598 | F35: =+B35/J33/J34 -> 0 | G35: =+C35/J33/J34 -> 0.00031162274 | H35: =+F35-G35 -> -0.00031162274
A36: pp voz | B36: =+'Seg Diario'!Y33 -> 0 | C36: =+'Seg Diario'!Z33 -> 0.68843479 | D36: =+B36/C36 -> 0 | E36: =+B36-C36 -> -0.68843479 | F36: =+B36/J33/J34 -> 0 | G36: =+C36/J33/J34 -> 0.0017789013 | H36: =+F36-G36 -> -0.0017789013

Sheet Asistencia
I1: Lunes | J1: Martes | K1: Miercoles | L1: Jueves | M1: Viernes | N1: Sabado | O1: Domingo | P1: Lunes | Q1: Martes | R1: Miercoles | S1: Jueves | T1: Viernes | U1: Sabado | V1: Domingo | W1: Lunes | X1: Martes | Y1: Miercoles | Z1: Jueves | AA1: Viernes | AB1: Sabado | AC1: Domingo | AD1: Lunes | AE1: Martes | AF1: Miercoles | AG1: Jueves | AH1: Viernes | AI1: Sabado | AJ1: Domingo | AK1: Lunes | AL1: Martes | AN1: Lunes | AO1: Martes | AP1: Miercoles | AQ1: Jueves | AR1: Viernes | AS1: Sabado | AT1: Domingo | AU1: Lunes | AV1: Martes | AW1: Miercoles | AX1: Jueves | AY1: Viernes | AZ1: Sabado | BA1: Domingo | BB1: Lunes | BC1: Martes | BD1: Miercoles | BE1: Jueves | BF1: Viernes | BG1: Sabado | BH1: Domingo | BI1: Lunes | BJ1: Martes | BK1: Miercoles | BL1: Jueves | BM1: Viernes | BN1: Sabado | BO1: Domingo | BP1: Lunes | BQ1: Martes
D2: =+SUBTOTAL(9,D4:D109) -> 0 | I2: =+SUBTOTAL(9,I4:I109) -> 0 | J2: =+SUBTOTAL(9,J4:J109) -> 0 | K2: =+SUBTOTAL(9,K4:K109) -> 0 | L2: =+SUBTOTAL(9,L4:L109) -> 0 | M2: =+SUBTOTAL(9,M4:M109) -> 0 | N2: =+SUBTOTAL(9,N4:N109) -> 0 | O2: =+SUBTOTAL(9,O4:O109) -> 0 | P2: =+SUBTOTAL(9,P4:P109) -> 0 | ... BR2: =+SUBTOTAL(9,BR4:BR109) -> 0
A3: LIDER | B3: ESTADO | C3: SUPERVISOR | D3: Pos | E3: IDPV | F3: NOMBRE_IDPV | G3: PLAZA | H3: CADENA | I3: 46174 | J3: 46175 | K3: 46176 | L3: 46177 | M3: 46178 | N3: 46179 | O3: 46180 | P3: 46181 | Q3: 46182 | R3: 46183 | S3: 46184 | T3: 46185 | U3: 46186 | V3: 46187 | W3: 46188 | X3: 46189 | Y3: 46190 | Z3: 46191 | AA3: 46192 | AB3: 46193 | AC3: 46194 | AD3: 46195 | AE3: 46196 | AF3: 46197 | AG3: 46198 | AH3: 46199 | AI3: 46200 | AJ3: 46201 | AK3: 46202 | AL3: 46203 | AN3: 46174 | AO3: 46175 | AP3: 46176 | AQ3: 46177 | AR3: 46178 | AS3: 46179 | AT3: 46180 | AU3: 46181 | AV3: 46182 | AW3: 46183 | AX3: 46184 | AY3: 46185 | AZ3: 46186 | BA3: 46187 | BB3: 46188 | BC3: 46189 | BD3: 46190 | BE3: 46191 | BF3: 46192 | BG3: 46193 | BH3: 46194 | BI3: 46195 | BJ3: 46196 | BK3: 46197 | BL3: 46198 | BM3: 46199 | BN3: 46200 | BO3: 46201 | BP3: 46202 | BQ3: 46203
A4: REYES ZARRABAL CRISTOPHER | B4: HIDALGO | C4: DANIEL BENJAMIN MARQUEZ BACA | E4: 2090171 | F4: COPPEL PLAZA DEL VALLE (194) | G4: Pachuca de Soto | H4: COPPEL
A5: REYES ZARRABAL CRISTOPHER | B5: HIDALGO | C5: CESAR GARRIDO BADILLO | E5: 2090172 | F5: COPPEL-CANADA OCAMPO (574) | G5: Pachuca de Soto | H5: COPPEL
A6: CALDERON GRACIAN ISRAEL | B6: TOLUCA | C6: ERIK ALEJANDRO GARCIA | E6: 2090173 | F6: COPPEL PILARES (TOL) (208) | G6: Metepec | H6: COPPEL
A7: SANCHEZ MEZA JOB | B7: TOLUCA | C7: EDGAR RAUL HERNANDEZ CERVANTES | E7: 2090174 | F7: COPPEL-CANADA JUAREZ (582) | G7: Toluca de Lerdo | H7: COPPEL
A8: SANCHEZ MEZA JOB | B8: TOLUCA | C8: EDGAR RAUL HERNANDEZ CERVANTES | E8: 2090175 | F8: COPPEL - JUAREZ II (64) | G8: Toluca de Lerdo | H8: COPPEL
A9: SANCHEZ MEZA JOB | B9: TOLUCA | C9: EDGAR RAUL HERNANDEZ CERVANTES | E9: 2090176 | F9: COPPEL - 5 DE MAYO (159) | G9: Toluca de Lerdo | H9: COPPEL
A10: SANCHEZ MEZA JOB | B10: TOLUCA | C10: EDSON FERREYRA FFLORES | E10: 2090552 | F10: SUBURBIA - METEPEC | G10: Metepec | H10: SUBURBIA
A11: SANCHEZ MEZA JOB | B11: TOLUCA | C11: EDGAR RAUL HERNANDEZ CERVANTES | E11: 2090559 | F11: SUBURBIA - GRAN PLAZA | G11: Toluca de Lerdo | H11: SUBURBIA
A12: REYES ZARRABAL CRISTOPHER | B12: HIDALGO | C12: CESAR GARRIDO BADILLO | E12: 2090618 | F12: COPPEL UNIVERSIDAD | G12: Mineral de La Reforma | H12: COPPEL
A13: SANCHEZ MEZA JOB | B13: TOLUCA | C13: ERIK ALEJANDRO GARCIA | E13: 2090742 | F13: COPPEL SENDERO | G13: Lerma | H13: COPPEL
A14: REYES ZARRABAL CRISTOPHER | B14: HIDALGO | C14: CESAR GARRIDO BADILLO | E14: 2090749 | F14: COPPEL CARRANZA LA COLCHONERA | G14: Pachuca de Soto | H14: COPPEL
A15: SANCHEZ MEZA JOB | B15: TOLUCA | C15: ERIK ALEJANDRO GARCIA | E15: 2090826 | F15: COPPEL CANADA GUADALUPE VICTORIA | G15: Ocoyoacac | H15: COPPEL
... A109: SANCHEZ MEZA JOB | B109: TOLUCA | C109: EDSON FERREYRA FFLORES | E109: 209003847 | F109: MEGA PLAZA MIA SANTIAGO T | G109: Toluca de Lerdo | H109: ELEKTRA

Sheet Cuota
D1: 1 | E1: 2 | F1: 3 | G1: 4 | H1: 5 | I1: 6 | J1: 7 | K1: 8 | L1: 9 | M1: 10 | N1: 11 | O1: 12 | P1: 13 | Q1: 14 | R1: 15 | S1: 16 | T1: 17 | U1: 18 | V1: 19 | W1: 20 | X1: 21 | Y1: 22 | Z1: 23 | AA1: 24 | AB1: 25 | AC1: 26 | AD1: 27 | AE1: 28 | AF1: 29 | AG1: 30 | AH1: 31 | AI1: 32 | AJ1: 33 | AK1: 34 | AL1: 35 | AM1: 36 | AN1: 37 | AO1: 38 | AP1: 39 | AQ1: 40 | AR1: 41 | AS1: 42 | AT1: 43 | AU1: 44 | AV1: 45 | AW1: 46 | AX1: 47 | AY1: 48 | AZ1: 49 | BA1: 50 | BB1: 51 | BC1: 52 | BD1: 53 | BE1: 54 | BF1: 55 | BG1: 56 | BH1: 57 | BI1: 58 | BJ1: 59 | BK1: 60 | BL1: 61 | BM1: 62 | BN1: 63 | BO1: 64 | BP1: 65 | BQ1: 66 | BR1: 67 | BS1: 68 | BT1: 69 | BU1: 70 | BV1: 71 | BW1: 72 | BX1: 73 | BY1: 74 | BZ1: 75 | CA1: 76 | CB1: 77 | CC1: 78 | CD1: 79 | CE1: 80 | CF1: 81 | CG1: 82 | CH1: 83 | CI1: 84 | CJ1: 85 | CK1: 86 | CL1: 87 | CM1: 88 | CN1: 89 | CO1: 90 | CP1: 91 | CQ1: 92 | CR1: 93 | CS1: 94 | CT1: 95 | CU1: 96 | CV1: 97 | CW1: 98 | CX1: 99 | CY1: 100 | CZ1: 101 | DA1: 102 | DB1: 103 | DC1: 104 | DD1: 105 | DE1: 106 | DF1: 107 | DG1: 108 | DH1: 109 | DI1: 110 | DJ1: 111 | DK1: 112 | DL1: 113 | DM1: 114 | DN1: 115 | DO1: 116 | DP1: 117 | DQ1: 118 | DR1: 119 | DS1: 120 | DT1: 121 | DU1: 122
H2: =+H5/$AS$5 -> 0.024385625 | I2: =+I5/$AS$5 -> 0.03395006 | J2: =+J5/$AS$5 -> 0.031588748 | K2: =+K5/$AS$5 -> 0.030344941 | L2: =+L5/$AS$5 -> 0.033109365 | M2: =+M5/$AS$5 -> 0.029811415 | N2: =+N5/$AS$5 -> 0.019015727 | O2: =+O5/$AS$5 -> 0.028200071 | ... AL2: =+AL5/$AS$5 -> 0 | AT2: =+AT5/$CE$5 -> 0.033244311 | AU2: =+AU5/$CE$5 -> 0.027203224 | AV2: =+AV5/$CE$5 -> 0.025575652 | AW2: =+AW5/$CE$5 -> 0.0250467 | AX2: =+AX5/$CE$5 -> 0.028588745 | AY2: =+AY5/$CE$5 -> 0.043860652 | AZ2: =+AZ5/$CE$5 -> 0.058550833 | BA2: =+BA5/$CE$5 -> 0.029753592 | ... BX2: =+BX5/$CE$5 -> 0 | CF2: =+CF5/$DQ$5 -> 0.03287931 | CG2: =+CG5/$DQ$5 -> 0.02815953 | CH2: =+CH5/$DQ$5 -> 0.026445145 | CI2: =+CI5/$DQ$5 -> 0.025845261 | CJ2: =+CJ5/$DQ$5 -> 0.029363323 | CK2: =+CK5/$DQ$5 -> 0.043167329 | CL2: =+CL5/$DQ$5 -> 0.055761946 | CM2: =+CM5/$DQ$5 -> 0.03002118 | ... DJ2: =+DJ5/$DQ$5 -> 0 | DR2: AL DIA (SOLO ACTUALIZAR)
E3: Dia de la semana | H3: Lunes | I3: Martes | J3: Miércoles | K3: Jueves | L3: Viernes | M3: Sábado | N3: Domingo | O3: Lunes | P3: Martes | Q3: Miércoles | R3: Jueves | S3: Viernes | T3: Sábado | U3: Domingo | V3: Lunes | W3: Martes | X3: Miércoles | Y3: Jueves | Z3: Viernes | AA3: Sábado | AB3: Domingo | AC3: Lunes | AD3: Martes | AE3: Miércoles | AF3: Jueves | AG3: Viernes | AH3: Sabado | AI3: Domingo | AJ3: Lunes | AK3: Martes | AT3: Miércoles | AU3: Jueves | AV3: Viernes | AW3: Sábado | AX3: Domingo | AY3: Lunes | AZ3: Martes | BA3: Miércoles | BB3: Jueves | BC3: Viernes | BD3: Sábado | BE3: Domingo | BF3: Lunes | BG3: Martes | BH3: Miércoles | BI3: Jueves | BJ3: Viernes | BK3: Sábado | BL3: Domingo | BM3: Lunes | BN3: Martes | BO3: Miércoles | BP3: Jueves | BQ3: Viernes | BR3: Sábado | BS3: Domingo | BT3: Lunes | BU3: Martes | BV3: Miércoles | BW3: Jueves | BX3: Viernes | CF3: Miércoles | CG3: Jueves | CH3: Viernes | CI3: Sábado | CJ3: Domingo | CK3: Lunes | CL3: Martes | CM3: Miércoles | CN3: Jueves | CO3: Viernes | CP3: Sábado | CQ3: Domingo | CR3: Lunes | CS3: Martes | CT3: Miércoles | CU3: Jueves | CV3: Viernes | CW3: Sábado | CX3: Domingo | CY3: Lunes | CZ3: Martes | DA3: Miércoles | DB3: Jueves | DC3: Viernes | DD3: Sábado | DE3: Domingo | DF3: Lunes | DG3: Martes | DH3: Miércoles | DI3: Jueves | DJ3: Viernes
E4: Cuota acumulada | H4: =+H5 -> 6.63289 | I4: =+H4+I5 -> 15.867306 | J4: =+I4+J5 -> 24.459446 | K4: =+J4+K5 -> 32.71327 | L4: =+K4+L5 -> 41.719017 | M4: =+L4+M5 -> 49.827722 | N4: =+M4+N5 -> 55 | O4: =+N4+O5 -> 62.670419 | P4: =+O4+P5 -> 71.623939 | ... AK4: =+AJ4+AK5 -> 272 | AT4: =+AT5 -> 39.826684 | AU4: =+AT4+AU5 -> 72.416147 | AV4: =+AU4+AV5 -> 103.05578 | AW4: =+AV4+AW5 -> 133.06172 | AX4: =+AW4+AX5 -> 167.31104 | AY4: =+AX4+AY5 -> 219.8561 | AZ4: =+AY4+AZ5 -> 290 | BA4: =+AZ4+BA5 -> 325.6448 | BB4: =+BA4+BB5 -> 355.19364 | ... BX4: =+BW4+BX5 -> 1198 | CF4: =+CF5 -> 79.469291 | CG4: =+CF4+CG5 -> 147.53088 | CH4: =+CG4+CH5 -> 211.44879 | CI4: =+CH4+CI5 -> 273.91679 | CJ4: =+CI4+CJ5 -> 344.88794 | CK4: =+CJ4+CK5 -> 449.22338 | CL4: =+CK4+CL5 -> 584 | CM4: =+CL4+CM5 -> 656.56119 | CN4: =+CM4+CN5 -> 718.79909 | ... DJ4: =+DI4+DJ5 -> 2417
E5: Cuota por dia | H5: =+SUBTOTAL(9,H7:H112) -> 6.63289 | I5: =+SUBTOTAL(9,I7:I112) -> 9.2344162 | J5: =+SUBTOTAL(9,J7:J112) -> 8.5921396 | K5: =+SUBTOTAL(9,K7:K112) -> 8.253824 | L5: =+SUBTOTAL(9,L7:L112) -> 9.0057474 | M5: =+SUBTOTAL(9,M7:M112) -> 8.108705 | N5: =+SUBTOTAL(9,N7:N112) -> 5.1722778 | O5: =+SUBTOTAL(9,O7:O112) -> 7.6704192 | ... DU5: =+SUBTOTAL(9,DU7:DU112) -> 33.009717
A6: LIDER | B6: ESTADO | C6: SUPERVISOR | D6: IDPV | E6: NOMBRE_IDPV | F6: PLAZA | G6: CADENA | H6: 1 porta | I6: 2 porta | J6: 3 porta | K6: 4 porta | L6: 5 porta | M6: 6 porta | N6: 7 porta | O6: 8 porta | P6: 9 porta | Q6: 10 porta | R6: 11 porta | S6: 12 porta | T6: 13 porta | U6: 14 porta | V6: 15 porta | W6: 16 porta | X6: 17 porta | Y6: 18 porta | Z6: 19 porta | AA6: 20 porta | AB6: 21 porta | AC6: 22 porta | AD6: 23 porta | AE6: 24 porta | AF6: 25 porta | AG6: 26 porta | AH6: 27 porta | AI6: 28 porta | AJ6: 29 porta | AK6: 30 porta | AL6: 31 porta | AM6: S 1 - 5 | AN6: S 6 - 12 | AO6: S 13 - 19 | AP6: S 20 - 26 | AQ6: S 27 - 30 | AR6: S | AS6: PORTA | AT6: 1 temm | AU6: 2 temm | AV6: 3 temm | AW6: 4 temm | AX6: 5 temm | AY6: 6 temm | AZ6: 7 temm | BA6: 8 temm | BB6: 9 temm | BC6: 10 temm | BD6: 11 temm | BE6: 12 temm | BF6: 13 temm | BG6: 14 temm | BH6: 15 temm | BI6: 16 temm | BJ6: 17 temm | BK6: 18 temm | BL6: 19 temm | BM6: 20 temm | BN6: 21 temm | BO6: 22 temm | BP6: 23 temm | BQ6: 24 temm | BR6: 25 temm | BS6: 26 temm | BT6: 27 temm | BU6: 28 temm | BV6: 29 temm | BW6: 30 temm | BX6: 31 temm | BY6: S 1 - 52 | BZ6: S 6 - 123 | CA6: S 13 - 194 | CB6: S 20 - 265 | CC6: S 27 - 306 | CD6: S7 | CE6: TEMM | CF6: 1 gral | CG6: 2 gral | CH6: 3 gral | CI6: 4 gral | CJ6: 5 gral | CK6: 6 gral | CL6: 7 gral | CM6: 8 gral | CN6: 9 gral | CO6: 10 gral | CP6: 11 gral | CQ6: 12 gral | CR6: 13 gral | CS6: 14 gral | CT6: 15 gral | CU6: 16 gral | CV6: 17 gral | CW6: 18 gral | CX6: 19 gral | CY6: 20 gral | CZ6: 21 gral | DA6: 22 gral | DB6: 23 gral | DC6: 24 gral | DD6: 25 gral | DE6: 26 gral | DF6: 27 gral | DG6: 28 gral | DH6: 29 gral | DI6: 30 gral | DJ6: 31 gral | DK6: S 1 - 53 | DL6: S 6 - 124 | DM6: S 13 - 195 | DN6: S 20 - 266 | DO6: S 27 - 307 | DP6: S8 | DQ6: PREPAGO | DR6: GRAL | DS6: TEMM14 | DT6: PORTA15 | DU6: PP VOZ
A7: REYES ZARRABAL CRISTOPHER | B7: HIDALGO | C7: DANIEL BENJAMIN MARQUEZ BACA | D7: 2090171 | E7: COPPEL PLAZA DEL VALLE (194) | F7: Pachuca de Soto | G7: COPPEL | H7: 0.241196 | I7: 0.33579695 | J7: 0.31244144 | K7: 0.30013906 | L7: 0.32748172 | M7: 0.294862 | N7: 0.18808283 | O7: 0.26913752 | P7: 0.31415861 | Q7: 0.27333324 | R7: 0.30502428 | S7: 0.3228919 | T7: 0.34035535 | U7: 0.17509911 | V7: 0.27992708 | W7: 0.32816099 | X7: 0.29945373 | Y7: 0.29261705 | Z7: 0.30749537 | AA7: 0.32200675 | AB7: 0.17033904 | AC7: 0.28924212 | AD7: 0.31855761 | AE7: 0.30646963 | AF7: 0.27458904 | AG7: 0.31217939 | AH7: 0.32607529 | AI7: 0.17288692 | AJ7: 0.98121347 | AK7: 1.0187865 | AL7: 0 | AM7: 2 | AN7: 2 | AO7: 2 | AP7: 2 | AQ7: 2 | AR7: 0 | AS7: 10 | AT7: 1.9276174 | AU7: 1.5568627 | AV7: 1.4641982 | AW7: 1.4347796 | AX7: 1.6399162 | AY7: 2.5466431 | AZ7: 3.4299827 | BA7: 1.7173362 | BB7: 1.4101726 | BC7: 1.284791 | BD7: 1.261926 | BE7: 1.7379029 | BF7: 2.8776436 | BG7: 3.7102278 | BH7: 1.9987819 | BI7: 1.5488182 | BJ7: 1.3898206 | BK7: 1.2902258 | BL7: 1.5787361 | BM7: 2.8693738 | BN7: 3.3242437 | BO7: 1.6341138 | BP7: 1.3155649 | BQ7: 1.2208915 | BR7: 1.1652179 | BS7: 1.5229476 | BT7: 2.8324357 | BU7: 3.3088284 | BV7: 2.6939963 | BW7: 2.3060037 | BX7: 0 | BY7: 14 | BZ7: 14 | CA7: 14 | CB7: 13 | CC7: 5 | CD7: 0 | CE7: 60 | CF7: 3.545683 | CG7: 3.0047044 | CH7: 2.8224956 | CI7: 2.7597612 | CJ7: 3.1387667 | CK7: 4.6605359 | CL7: 6.0680532 | CM7: 3.2131424 | CN7: 2.7315974 | CO7: 2.4758321 | CP7: 2.468326 | CQ7: 3.302154 | CR7: 5.2734586 | CS7: 6.5354895 | CT7: 3.5636402 | CU7: 2.872648 | CV7: 2.5827304 | CW7: 2.4122737 | CX7: 2.9011332 | CY7: 5.035978 | CZ7: 5.6315966 | DA7: 3.0546655 | DB7: 2.5448982 | DC7: 2.3725937 | DD7: 2.2464963 | DE7: 2.8894754 | DF7: 5.1194281 | DG7: 5.7724427 | DH7: 4.8371453 | DI7: 4.1628547 | DK7: 26 | DL7: 26 | DM7: 25 | DN7: 24 | DO7: 9 | DQ7: 110 | DR7: =+SUM(Tabla2[[#This Row],[1 gral]:[1 gral]]) -> 3.545683 | DS7: =+SUM(Tabla2[[#This Row],[1 temm]:[1 temm]]) -> 1.9276174 | DT7: =+SUM(Tabla2[[#This Row],[1 porta]:[1 porta]]) -> 0.241196 | DU7: =+Tabla2[[#This Row],[GRAL]]-(Tabla2[[#This Row],[TEMM14]]+Tabla2[[#This Row],[PORTA15]]) -> 1.3768696
A8: REYES ZARRABAL CRISTOPHER | B8: HIDALGO | C8: VIRGINIA MIRANDA OSORIO | D8: 2090172 | E8: COPPEL-CANADA OCAMPO (574) | F8: Pachuca de Soto | G8: COPPEL | H8: 0.241196 | I8: 0.33579695 | J8: 0.31244144 | K8: 0.30013906 | L8: 0.32748172 | M8: 0.294862 | N8: 0.18808283 | O8: 0.26913752 | P8: 0.31415861 | Q8: 0.27333324 | R8: 0.30502428 | S8: 0.3228919 | T8: 0.34035535 | U8: 0.17509911 | V8: 0.27992708 | W8: 0.32816099 | X8: 0.29945373 | Y8: 0.29261705 | Z8: 0.30749537 | AA8: 0.32200675 | AB8: 0.17033904 | AC8: 0.28924212 | AD8: 0.31855761 | AE8: 0.30646963 | AF8: 0.27458904 | AG8: 0.31217939 | AH8: 0.32607529 | AI8: 0.17288692 | AJ8: 0.98121347 | AK8: 1.0187865 | AL8: 0 | AM8: 2 | AN8: 2 | AO8: 2 | AP8: 2 | AQ8: 2 | AR8: 0 | AS8: 10 | AT8: 1.6522435 | AU8: 1.3344537 | AV8: 1.2550271 | AW8: 1.2298111 | AX8: 1.4056425 | AY8: 2.182837 | AZ8: 2.9399852 | BA8: 1.4720024 | BB8: 1.2087194 | BC8: 1.1012494 | BD8: 1.0816509 | BE8: 1.489631 | BF8: 2.4665516 | BG8: 3.1801952 | BH8: 1.5704715 | BI8: 1.2169286 | BJ8: 1.0920019 | BK8: 1.0137488 | BL8: 1.2404355 | BM8: 2.254508 | BN8: 2.6119058 | BO8: 1.3827117 | BP8: 1.1131703 | BQ8: 1.033062 | BR8: 0.98595365 | BS8: 1.288648 | BT8: 2.3966764 | BU8: 2.7997779 | BV8: 1.1016948 | BW8: 0.8983052 | BX8: 0 | BY8: 12 | BZ8: 12 | CA8: 11 | CB8: 11 | CC8: 2 | CD8: 0 | CE8: 48 | CF8: 2.9949352 | CG8: 2.5598865 | CH8: 2.4041532 | CI8: 2.3498242 | CJ8: 2.6702192 | CK8: 3.9329236 | CL8: 5.0880581 | CM8: 2.7224749 | CN8: 2.3286909 | CO8: 2.108749 | CP8: 2.1077757 | CQ8: 2.8056103 | CR8: 4.4512748 | CS8: 5.4754245 | CT8: 2.8497895 | CU8: 2.3194986 | CV8: 2.0863659 | CW8: 1.9514788 | CX8: 2.3372989 | CY8: 4.0112016 | CZ8: 4.4443667 | DA8: 2.5518613 | DB8: 2.140109 | DC8: 1.9969348 | DD8: 1.8879677 | DE8: 2.4208761 | DF8: 4.2479094 | DG8: 4.7543417 | DH8: 3.1846031 | DI8: 2.8153969 | DK8: 22 | DL8: 22 | DM8: 20 | DN8: 20 | DO8: 6 | DQ8: 90 | DR8: =+SUM(Tabla2[[#This Row],[1 gral]:[1 gral]]) -> 2.9949352 | DS8: =+SUM(Tabla2[[#This Row],[1 temm]:[1 temm]]) -> 1.6522435 | DT8: =+SUM(Tabla2[[#This Row],[1 porta]:[1 porta]]) -> 0.241196 | DU8: =+Tabla2[[#This Row],[GRAL]]-(Tabla2[[#This Row],[TEMM14]]+Tabla2[[#This Row],[PORTA15]]) -> 1.1014957
A9: CALDERON GRACIAN ISRAEL | B9: TOLUCA | C9: ERIK ALEJANDRO GARCIA | D9: 2090173 | E9: COPPEL PILARES (TOL) (208) | F9: Metepec | G9: COPPEL | H9: 0 | I9: 0 | J9: 0 | K9: 0 | L9: 0 | M9: 0 | N9: 0 | O9: 0 | P9: 0 | Q9: 0 | R9: 0 | S9: 0 | T9: 0 | U9: 0 | V9: 0 | W9: 0 | X9: 0 | Y9: 0 | Z9: 0 | AA9: 0 | AB9: 0 | AC9: 0 | AD9: 0 | AE9: 0 | AF9: 0 | AG9: 0 | AH9: 0 | AI9: 0 | AJ9: 0.98121347 | AK9: 1.0187865 | AL9: 0 | AM9: 0 | AN9: 0 | AO9: 0 | AP9: 0 | AQ9: 2 | AR9: 0 | AS9: 2 | AT9: 0.96380871 | AU9: 0.77843134 | AV9: 0.73209912 | AW9: 0.71738981 | AX9: 0.81995811 | AY9: 1.2733216 | AZ9: 1.7149913 | BA9: 0.85866808 | BB9: 0.7050863 | BC9: 0.6423955 | BD9: 0.63096301 | BE9: 0.86895144 | BF9: 1.4388218 | BG9: 1.8551139 | BH9: 0.85662081 | BI9: 0.66377922 | BJ9: 0.59563738 | BK9: 0.5529539 | BL9: 0.67660118 | BM9: 1.2297316 | BN9: 1.4246759 | BO9: 0.75420638 | BP9: 0.6071838 | BQ9: 0.56348839 | BR9: 0.5377929 | BS9: 0.70289891 | BT9: 1.307278 | BU9: 1.5271516 | BV9: 0.5508474 | BW9: 0.4491526 | BX9: 0 | BY9: 7 | BZ9: 7 | CA9: 6 | CB9: 6 | CC9: 1 | CD9: 0 | CE9: 27 | CF9: 1.6522435 | CG9: 1.3344537 | CH9: 1.2550271 | CI9: 1.2298111 | CJ9: 1.4056425 | CK9: 2.182837 | CL9: 2.9399852 | CM9: 1.4720024 | CN9: 1.2087194 | CO9: 1.1012494 | CP9: 1.0816509 | CQ9: 1.489631 | CR9: 2.4665516 | CS9: 3.1801952 | CT9: 1.5704715 | CU9: 1.2169286 | CV9: 1.0920019 | CW9: 1.0137488 | CX9: 1.2404355 | CY9: 2.254508 | CZ9: 2.6119058 | DA9: 1.3827117 | DB9: 1.1131703 | DC9: 1.033062 | DD9: 0.98595365 | DE9: 1.288648 | DF9: 2.3966764 | DG9: 2.7997779 | DH9: 1.5320609 | DI9: 1.4679391 | DK9: 12 | DL9: 12 | DM9: 11 | DN9: 11 | DO9: 3 | DQ9: 49 | DR9: =+SUM(Tabla2[[#This Row],[1 gral]:[1 gral]]) -> 1.6522435 | DS9: =+SUM(Tabla2[[#This Row],[1 temm]:[1 temm]]) -> 0.96380871 | DT9: =+SUM(Tabla2[[#This Row],[1 porta]:[1 porta]]) -> 0 | DU9: =+Tabla2[[#This Row],[GRAL]]-(Tabla2[[#This Row],[TEMM14]]+Tabla2[[#This Row],[PORTA15]]) -> 0.68843479
A10: SANCHEZ MEZA JOB | B10: TOLUCA | C10: EDGAR RAUL HERNANDEZ CERVANTES | D10: 2090174 | E10: COPPEL-CANADA JUAREZ (582) | F10: Toluca de Lerdo | G10: COPPEL | H10: 0.120598 | I10: 0.16789848 | J10: 0.15622072 | K10: 0.15006953 | L10: 0.16374086 | M10: 0.147431 | N10: 0.094041414 | O10: 0.13456876 | P10: 0.1570793 | Q10: 0.13666662 | R10: 0.15251214 | S10: 0.16144595 | T10: 0.17017768 | U10: 0.087549554 | V10: 0.13996354 | W10: 0.16408049 | X10: 0.14972686 | Y10: 0.14630852 | Z10: 0.15374769 | AA10: 0.16100337 | AB10: 0.085169521 | AC10: 0.14462106 | AD10: 0.1592788 | AE10: 0.15323481 | AF10: 0.13729452 | AG10: 0.1560897 | AH10: 0.16303765 | AI10: 0.086443459 | AJ10: 0 | AK10: 0 | AL10: 0 | AM10: 1 | AN10: 1 | AO10: 1 | AP10: 1 | AQ10: 0 | AR10: 0 | AS10: 4 | AT10: 0.96380871 | AU10: 0.77843134 | AV10: 0.73209912 | AW10: 0.71738981 | AX10: 0.81995811 | AY10: 1.2733216 | AZ10: 1.7149913 | BA10: 0.85866808 | BB10: 0.7050863 | BC10: 0.6423955 | BD10: 0.63096301 | BE10: 0.86895144 | BF10: 1.4388218 | BG10: 1.8551139 | BH10: 0.99939094 | BI10: 0.77440909 | BJ10: 0.69491028 | BK10: 0.64511289 | BL10: 0.78936805 | BM10: 1.4346869 | BN10: 1.6621219 | BO10: 0.87990745 | BP10: 0.7083811 | BQ10: 0.65740312 | BR10: 0.62742505 | BS10: 0.82004872 | BT10: 1.5251577 | BU10: 1.7816769 | BV10: 0.5508474 | BW10: 0.4491526 | BX10: 0 | BY10: 7 | BZ10: 7 | CA10: 7 | CB10: 7 | CC10: 1 | CD10: 0 | CE10: 29 | CF10: 1.7728415 | CG10: 1.5023522 | CH10: 1.4112478 | CI10: 1.3798806 | CJ10: 1.5693833 | CK10: 2.330268 | CL10: 3.0340266 | CM10: 1.6065712 | CN10: 1.3657987 | CO10: 1.237916 | CP10: 1.234163 | CQ10: 1.651077 | CR10: 2.6367293 | CS10: 3.2677448 | CT10: 1.8532052 | CU10: 1.4916389 | CV10: 1.3410016 | CW10: 1.2522163 | CX10: 1.5069501 | CY10: 2.6204666 | CZ10: 2.9345213 | DA10: 1.6530338 | DB10: 1.3736464 | DC10: 1.2802116 | DD10: 1.2128803 | DE10: 1.5618875 | DF10: 2.7775937 | DG10: 3.1407466 | DH10: 1.6525422 | DI10: 1.3474578 | DK10: 13 | DL10: 13 | DM10: 13 | DN10: 13 | DO10: 3 | DQ10: 55 | DR10: =+SUM(Tabla2[[#This Row],[1 gral]:[1 gral]]) -> 1.7728415 | DS10: =+SUM(Tabla2[[#This Row],[1 temm]:[1 temm]]) -> 0.96380871 | DT10: =+SUM(Tabla2[[#This Row],[1 porta]:[1 porta]]) -> 0.120598 | DU10: =+Tabla2[[#This Row],[GRAL]]-(Tabla2[[#This Row],[TEMM14]]+Tabla2[[#This Row],[PORTA15]]) -> 0.68843479
A11: SANCHEZ MEZA JOB | B11: TOLUCA | C11: EDGAR RAUL HERNANDEZ CERVANTES | D11: 2090175 | E11: COPPEL - JUAREZ II (64) | F11: Toluca de Lerdo | G11: COPPEL | H11: 0.241196 | I11: 0.33579695 | J11: 0.31244144 | K11: 0.30013906 | L11: 0.32748172 | M11: 0.294862 | N11: 0.18808283 | O11: 0.26913752 | P11: 0.31415861 | Q11: 0.27333324 | R11: 0.30502428 | S11: 0.3228919 | T11: 0.34035535 | U11: 0.17509911 | V11: 0.27992708 | W11: 0.32816099 | X11: 0.29945373 | Y11: 0.29261705 | Z11: 0.30749537 | AA11: 0.32200675 | AB11: 0.17033904 | AC11: 0.28924212 | AD11: 0.31855761 | AE11: 0.30646963 | AF11: 0.27458904 | AG11: 0.31217939 | AH11: 0.32607529 | AI11: 0.17288692 | AJ11: 0.98121347 | AK11: 1.0187865 | AL11: 0 | AM11: 2 | AN11: 2 | AO11: 2 | AP11: 2 | AQ11: 2 | AR11: 0 | AS11: 10 | AT11: 2.6160522 | AU11: 2.1128851 | AV11: 1.9871262 | AW11: 1.9472009 | AX11: 2.2256006 | AY11: 3.4561585 | AZ11: 4.6549765 | BA11: 2.3306705 | BB11: 1.9138057 | BC11: 1.7436449 | BD11: 1.7126139 | BE11: 2.3585825 | BF11: 3.9053734 | BG11: 5.0353091 | BH11: 2.5698624 | BI11: 1.9913377 | BJ11: 1.7869121 | BK11: 1.6588617 | BL11: 2.0298036 | BM11: 3.6891949 | BN11: 4.2740277 | BO11: 2.2626192 | BP11: 1.8215514 | BQ11: 1.6904652 | BR11: 1.6133787 | BS11: 2.1086967 | BT11: 3.9218341 | BU11: 4.5814548 | BV11: 2.754237 | BW11: 2.245763 | BX11: 0 | BY11: 19 | BZ11: 19 | CA11: 18 | CB11: 18 | CC11: 5 | CD11: 0 | CE11: 79 | CF11: 4.0964308 | CG11: 3.4495223 | CH11: 3.2408379 | CI11: 3.1696983 | CJ11: 3.6073141 | CK11: 5.3881483 | CL11: 7.0480482 | CM11: 3.7038098 | CN11: 3.1345038 | CO11: 2.8429152 | CP11: 2.8288763 | CQ11: 3.7986977 | CR11: 6.0956425 | CS11: 7.5955546 | CT11: 3.9919506 | CU11: 3.2045376 | CV11: 2.8805491 | CW11: 2.6887506 | CX11: 3.2394338 | CY11: 5.6508438 | CZ11: 6.3439345 | DA11: 3.5574698 | DB11: 2.9496874 | DC11: 2.7482527 | DD11: 2.6050249 | DE11: 3.3580747 | DF11: 5.9909468 | DG11: 6.7905438 | DH11: 4.2862979 | DI11: 3.7137021 | DK11: 30 | DL11: 30 | DM11: 28 | DN11: 28 | DO11: 8 | DQ11: 124 | DR11: =+SUM(Tabla2[[#This Row],[1 gral]:[1 gral]]) -> 4.0964308 | DS11: =+SUM(Tabla2[[#This Row],[1 temm]:[1 temm]]) -> 2.6160522 | DT11: =+SUM(Tabla2[[#This Row],[1 porta]:[1 porta]]) -> 0.241196 | DU11: =+Tabla2[[#This Row],[GRAL]]-(Tabla2[[#This Row],[TEMM14]]+Tabla2[[#This Row],[PORTA15]]) -> 1.2391826
A12: SANCHEZ MEZA JOB | B12: TOLUCA | C12: EDGAR RAUL HERNANDEZ CERVANTES | D12: 2090176 | E12: COPPEL - 5 DE MAYO (159) | F12: Toluca de Lerdo | G12: COPPEL | H12: 0.120598 | I12: 0.16789848 | J12: 0.15622072 | K12: 0.15006953 | L12: 0.16374086 | M12: 0.147431 | N12: 0.094041414 | O12: 0.13456876 | P12: 0.1570793 | Q12: 0.13666662 | R12: 0.15251214 | S12: 0.16144595 | T12: 0.17017768 | U12: 0.087549554 | V12: 0.13996354 | W12: 0.16408049 | X12: 0.14972686 | Y12: 0.14630852 | Z12: 0.15374769 | AA12: 0.16100337 | AB12: 0.085169521 | AC12: 0.14462106 | AD12: 0.1592788 | AE12: 0.15323481 | AF12: 0.13729452 | AG12: 0.1560897 | AH12: 0.16303765 | AI12: 0.086443459 | AJ12: 0.98121347 | AK12: 1.0187865 | AL12: 0 | AM12: 1 | AN12: 1 | AO12: 1 | AP12: 1 | AQ12: 2 | AR12: 0 | AS12: 6 | AT12: 3.8552348 | AU12: 3.1137254 | AV12: 2.9283965 | AW12: 2.8695592 | AX12: 3.2798324 | AY12: 5.0932863 | AZ12: 6.8599654 | BA12: 3.4346723 | BB12: 2.8203452 | BC12: 2.569582 | BD12: 2.523852 | BE12: 3.4758058 | BF12: 5.7552872 | BG12: 7.4204555 | BH12: 3.7120235 | BI12: 2.8763766 | BJ12: 2.5810953 | BK12: 2.3961336 | BL12: 2.9319385 | BM12: 5.328837 | BN12: 6.1735955 | BO12: 3.2682277 | BP12: 2.6311298 | BQ12: 2.441783 | BR12: 2.3304359 | BS12: 3.0458953 | BT12: 5.6648715 | BU12: 6.6176569 | BV12: 3.3050844 | BW12: 2.6949156 | BX12: 0 | BY12: 28 | BZ12: 28 | CA12: 26 | CB12: 26 | CC12: 6 | CD12: 0 | CE12: 114 | CF12: 4.8019546 | CG12: 3.9488507 | CH12: 3.7121307 | CI12: 3.6345343 | CJ12: 4.1463945 | CK12: 6.3321358 | CL12: 8.4239994 | CM12: 4.3052423 | CN12: 3.5817842 | CO12: 3.2568733 | CP12: 3.2171896 | CQ12: 4.3820672 | CR12: 7.1587407 | CS12: 9.0981027 | CT12: 4.7086078 | CU12: 3.7042363 | CV12: 3.3264596 | CW12: 3.095396 | CX12: 3.7622873 | CY12: 6.719572 | CZ12: 7.6834409 | DA12: 4.1670551 | DB12: 3.3975924 | DC12: 3.1585062 | DD12: 3.0055233 | DE12: 3.9048839 | DF12: 7.1351872 | DG12: 8.2312519 | DH12: 4.8371453 | DI12: 4.1628547 | DK12: 35 | DL12: 35 | DM12: 33 | DN12: 33 | DO12: 9 | DQ12: 145 | DR12: =+SUM(Tabla2[[#This Row],[1 gral]:[1 gral]]) -> 4.8019546 | DS12: =+SUM(Tabla2[[#This Row],[1 temm]:[1 temm]]) -> 3.8552348 | DT12: =+SUM(Tabla2[[#This Row],[1 porta]:[1 porta]]) -> 0.120598 | DU12: =+Tabla2[[#This Row],[GRAL]]-(Tabla2[[#This Row],[TEMM14]]+Tabla2[[#This Row],[PORTA15]]) -> 0.82612175
A13: SANCHEZ MEZA JOB | B13: TOLUCA | C13: EDSON FERREYRA FFLORES | D13: 2090552 | E13: SUBURBIA - METEPEC | F13: Metepec | G13: SUBURBIA | H13: 0.120598 | I13: 0.16789848 | J13: 0.15622072 | K13: 0.15006953 | L13: 0.16374086 | M13: 0.147431 | N13: 0.094041414 | O13: 0.13456876 | P13: 0.1570793 | Q13: 0.13666662 | R13: 0.15251214 | S13: 0.16144595 | T13: 0.17017768 | U13: 0.087549554 | V13: 0.13996354 | W13: 0.16408049 | X13: 0.14972686 | Y13: 0.14630852 | Z13: 0.15374769 | AA13: 0.16100337 | AB13: 0.085169521 | AC13: 0.14462106 | AD13: 0.1592788 | AE13: 0.15323481 | AF13: 0.13729452 | AG13: 0.1560897 | AH13: 0.16303765 | AI13: 0.086443459 | AJ13: 0.49060674 | AK13: 0.50939326 | AL13: 0 | AM13: 1 | AN13: 1 | AO13: 1 | AP13: 1 | AQ13: 1 | AR13: 0 | AS13: 5 | AT13: 1.3768696 | AU13: 1.1120448 | AV13: 1.0458559 | AW13: 1.0248426 | AX13: 1.1713687 | AY13: 1.8190308 | AZ13: 2.4499876 | BA13: 1.2266687 | BB13: 1.0072661 | BC13: 0.91770786 | BD13: 0.90137573 | BE13: 1.2413592 | BF13: 2.0554597 | BG13: 2.6501627 | BH13: 1.2849312 | BI13: 0.99566883 | BJ13: 0.89345607 | BK13: 0.82943085 | BL13: 1.0149018 | BM13: 1.8445974 | BN13: 2.1370138 | BO13: 1.1313096 | BP13: 0.9107757 | BQ13: 0.84523258 | BR13: 0.80668935 | BS13: 1.0543484 | BT13: 1.9609171 | BU13: 2.2907274 | BV13: 0.5508474 | BW13: 0.4491526 | BX13: 0 | BY13: 10 | BZ13: 10 | CA13: 9 | CB13: 9 | CC13: 1 | CD13: 0 | CE13: 39 | CF13: 1.7728415 | CG13: 1.5023522 | CH13: 1.4112478 | CI13: 1.3798806 | CJ13: 1.5693833 | CK13: 2.330268 | CL13: 3.0340266 | CM13: 1.6065712 | CN13: 1.3657987 | CO13: 1.237916 | CP13: 1.234163 | CQ13: 1.651077 | CR13: 2.6367293 | CS13: 3.2677448 | CT13: 1.710435 | CU13: 1.3810091 | CV13: 1.2417287 | CW13: 1.1600573 | CX13: 1.3941832 | CY13: 2.4155113 | CZ13: 2.6970753 | DA13: 1.5273328 | DB13: 1.2724491 | DC13: 1.1862969 | DD13: 1.1232482 | DE13: 1.4447377 | DF13: 2.559714 | DG13: 2.8862214 | DH13: 1.5923015 | DI13: 1.4076985 | DK13: 13 | DL13: 13 | DM13: 12 | DN13: 12 | DO13: 3 | DQ13: 53 | DR13: =+SUM(Tabla2[[#This Row],[1 gral]:[1 gral]]) -> 1.7728415 | DS13: =+SUM(Tabla2[[#This Row],[1 temm]:[1 temm]]) -> 1.3768696 | DT13: =+SUM(Tabla2[[#This Row],[1 porta]:[1 porta]]) -> 0.120598 | DU13: =+Tabla2[[#This Row],[GRAL]]-(Tabla2[[#This Row],[TEMM14]]+Tabla2[[#This Row],[PORTA15]]) -> 0.27537392
A14: SANCHEZ MEZA JOB | B14: TOLUCA | C14: EDGAR RAUL HERNANDEZ CERVANTES | D14: 2090559 | E14: SUBURBIA - GRAN PLAZA | F14: Toluca de Lerdo | G14: SUBURBIA | H14: 0.120598 | I14: 0.16789848 | J14: 0.15622072 | K14: 0.15006953 | L14: 0.16374086 | M14: 0.147431 | N14: 0.094041414 | O14: 0.13456876 | P14: 0.1570793 | Q14: 0.13666662 | R14: 0.15251214 | S14: 0.16144595 | T14: 0.17017768 | U14: 0.087549554 | V14: 0.13996354 | W14: 0.16408049 | X14: 0.14972686 | Y14: 0.14630852 | Z14: 0.15374769 | AA14: 0.16100337 | AB14: 0.085169521 | AC14: 0.14462106 | AD14: 0.1592788 | AE14: 0.15323481 | AF14: 0.13729452 | AG14: 0.1560897 | AH14: 0.16303765 | AI14: 0.086443459 | AJ14: 0 | AK14: 0 | AL14: 0 | AM14: 1 | AN14: 1 | AO14: 1 | AP14: 1 | AQ14: 0 | AR14: 0 | AS14: 4 | AT14: 1.1014957 | AU14: 0.88963582 | AV14: 0.83668471 | AW14: 0.81987406 | AX14: 0.93709498 | AY14: 1.4552246 | AZ14: 1.9599901 | BA14: 0.98133495 | BB14: 0.80581292 | BC14: 0.73416629 | BD14: 0.72110058 | BE14: 0.99308736 | BF14: 1.6443678 | BG14: 2.1201301 | BH14: 0.99939094 | BI14: 0.77440909 | BJ14: 0.69491028 | BK14: 0.64511289 | BL14: 0.78936805 | BM14: 1.4346869 | BN14: 1.6621219 | BO14: 0.87990745 | BP14: 0.7083811 | BQ14: 0.65740312 | BR14: 0.62742505 | BS14: 0.82004872 | BT14: 1.5251577 | BU14: 1.7816769 | BV14: 0.5508474 | BW14: 0.4491526 | BX14: 0 | BY14: 8 | BZ14: 8 | CA14: 7 | CB14: 7 | CC14: 1 | CD14: 0 | CE14: 31 | CF14: 1.9105285 | CG14: 1.6135567 | CH14: 1.5158334 | CI14: 1.4823649 | CJ14: 1.6865202 | CK14: 2.5121711 | CL14: 3.2790253 | CM14: 1.729238 | CN14: 1.4665253 | CO14: 1.3296868 | CP14: 1.3243006 | CQ14: 1.7752129 | CR14: 2.8422753 | CS14: 3.532761 | CT14: 1.710435 | CU14: 1.3810091 | CV14: 1.2417287 | CW14: 1.1600573 | CX14: 1.3941832 | CY14: 2.4155113 | CZ14: 2.6970753 | DA14: 1.5273328 | DB14: 1.2724491 | DC14: 1.1862969 | DD14: 1.1232482 | DE14: 1.4447377 | DF14: 2.559714 | DG14: 2.8862214 | DH14: 1.1016948 | DI14: 0.8983052 | DK14: 14 | DL14: 14 | DM14: 12 | DN14: 12 | DO14: 2 | DQ14: 54 | DR14: =+SUM(Tabla2[[#This Row],[1 gral]:[1 gral]]) -> 1.9105285 | DS14: =+SUM(Tabla2[[#This Row],[1 temm]:[1 temm]]) -> 1.1014957 | DT14: =+SUM(Tabla2[[#This Row],[1 porta]:[1 porta]]) -> 0.120598 | DU14: =+Tabla2[[#This Row],[GRAL]]-(Tabla2[[#This Row],[TEMM14]]+Tabla2[[#This Row],[PORTA15]]) -> 0.68843479
A15: REYES ZARRABAL CRISTOPHER | B15: HIDALGO | C15: VIRGINIA MIRANDA OSORIO | D15: 2090618 | E15: COPPEL UNIVERSIDAD | F15: Mineral de La Reforma | G15: COPPEL | H15: 0.120598 | I15: 0.16789848 | J15: 0.15622072 | K15: 0.15006953 | L15: 0.16374086 | M15: 0.147431 | N15: 0.094041414 | O15: 0.13456876 | P15: 0.1570793 | Q15: 0.13666662 | R15: 0.15251214 | S15: 0.16144595 | T15: 0.17017768 | U15: 0.087549554 | V15: 0.13996354 | W15: 0.16408049 | X15: 0.14972686 | Y15: 0.14630852 | Z15: 0.15374769 | AA15: 0.16100337 | AB15: 0.085169521 | AC15: 0.14462106 | AD15: 0.1592788 | AE15: 0.15323481 | AF15: 0.13729452 | AG15: 0.1560897 | AH15: 0.16303765 | AI15: 0.086443459 | AJ15: 0.49060674 | AK15: 0.50939326 | AL15: 0 | AM15: 1 | AN15: 1 | AO15: 1 | AP15: 1 | AQ15: 1 | AR15: 0 | AS15: 5 | AT15: 1.1014957 | AU15: 0.88963582 | AV15: 0.83668471 | AW15: 0.81987406 | AX15: 0.93709498 | AY15: 1.4552246 | AZ15: 1.9599901 | BA15: 0.98133495 | BB15: 0.80581292 | BC15: 0.73416629 | BD15: 0.72110058 | BE15: 0.99308736 | BF15: 1.6443678 | BG15: 2.1201301 | BH15: 0.99939094 | BI15: 0.77440909 | BJ15: 0.69491028 | BK15: 0.64511289 | BL15: 0.78936805 | BM15: 1.4346869 | BN15: 1.6621219 | BO15: 0.87990745 | BP15: 0.7083811 | BQ15: 0.65740312 | BR15: 0.62742505 | BS15: 0.82004872 | BT15: 1.5251577 | BU15: 1.7816769 | BV15: 1.1016948 | BW15: 0.8983052 | BX15: 0 | BY15: 8 | BZ15: 8 | CA15: 7 | CB15: 7 | CC15: 2 | CD15: 0 | CE15: 32 | CF15: 2.3235893 | CG15: 1.9471701 | CH15: 1.8295901 | CI15: 1.7898177 | CJ15: 2.0379308 | CK15: 3.0578803 | CL15: 4.0140216 | CM15: 2.0972387 | CN15: 1.7687051 | CO15: 1.6049992 | CP15: 1.5947133 | CQ15: 2.1476207 | CR15: 3.4589132 | CS15: 4.3278098 | CT15: 2.2815156 | CU15: 1.8235285 | CV15: 1.6388203 | CW15: 1.5286933 | CX15: 1.8452506 | CY15: 3.2353324 | CZ15: 3.6468592 | DA15: 1.904436 | DB15: 1.576041 | DC15: 1.4680411 | DD15: 1.3921446 | DE15: 1.7961871 | DF15: 3.2133531 | DG15: 3.6497972 | DH15: 2.6939963 | DI15: 2.3060037 | DK15: 17 | DL15: 17 | DM15: 16 | DN15: 15 | DO15: 5 | DQ15: 70 | DR15: =+SUM(Tabla2[[#This Row],[1 gral]:[1 gral]]) -> 2.3235893 | DS15: =+SUM(Tabla2[[#This Row],[1 temm]:[1 temm]]) -> 1.1014957 | DT15: =+SUM(Tabla2[[#This Row],[1 porta]:[1 porta]]) -> 0.120598 | DU15: =+Tabla2[[#This Row],[GRAL]]-(Tabla2[[#This Row],[TEMM14]]+Tabla2[[#This Row],[PORTA15]]) -> 1.1014957
A16: SANCHEZ MEZA JOB | B16: TOLUCA | C16: ERIK ALEJANDRO GARCIA | D16: 2090742 | E16: COPPEL SENDERO | F16: Lerma | G16: COPPEL | H16: 0.241196 | I16: 0.33579695 | J16: 0.31244144 | K16: 0.30013906 | L16: 0.32748172 | M16: 0.294862 | N16: 0.18808283 | O16: 0.26913752 | P16: 0.31415861 | Q16: 0.27333324 | R16: 0.30502428 | S16: 0.3228919 | T16: 0.34035535 | U16: 0.17509911 | V16: 0.27992708 | W16: 0.32816099 | X16: 0.29945373 | Y16: 0.29261705 | Z16: 0.30749537 | AA16: 0.32200675 | AB16: 0.17033904 | AC16: 0.28924212 | AD16: 0.31855761 | AE16: 0.30646963 | AF16: 0.27458904 | AG16: 0.31217939 | AH16: 0.32607529 | AI16: 0.17288692 | AJ16: 0.98121347 | AK16: 1.0187865 | AL16: 0 | AM16: 2 | AN16: 2 | AO16: 2 | AP16: 2 | AQ16: 2 | AR16: 0 | AS16: 10 | AT16: 2.4783653 | AU16: 2.0016806 | AV16: 1.8825406 | AW16: 1.8447166 | AX16: 2.1084637 | AY16: 3.2742555 | AZ16: 4.4099778 | BA16: 2.2080036 | BB16: 1.8130791 | BC16: 1.6518741 | BD16: 1.6224763 | BE16: 2.2344466 | BF16: 3.6998275 | BG16: 4.7702928 | BH16: 2.4270923 | BI16: 1.8807078 | BJ16: 1.6876393 | BK16: 1.5667027 | BL16: 1.9170367 | BM16: 3.4842396 | BN16: 4.0365817 | BO16: 2.1369181 | BP16: 1.7203541 | BQ16: 1.5965504 | BR16: 1.5237465 | BS16: 1.9915469 | BT16: 3.7039544 | BU16: 4.3269295 | BV16: 2.754237 | BW16: 2.245763 | BX16: 0 | BY16: 18 | BZ16: 18 | CA16: 17 | CB16: 17 | CC16: 5 | CD16: 0 | CE16: 75 | CF16: 3.9587439 | CG16: 3.3383178 | CH16: 3.1362523 | CI16: 3.067214 | CJ16: 3.4901773 | CK16: 5.2062452 | CL16: 6.8030495 | CM16: 3.581143 | CN16: 3.0337772 | CO16: 2.7511445 | CP16: 2.7387387 | CQ16: 3.6745617 | CR16: 5.8900966 | CS16: 7.3305383 | CT16: 3.9919506 | CU16: 3.2045376 | CV16: 2.8805491 | CW16: 2.6887506 | CX16: 3.2394338 | CY16: 5.6508438 | CZ16: 6.3439345 | DA16: 3.5574698 | DB16: 2.9496874 | DC16: 2.7482527 | DD16: 2.6050249 | DE16: 3.3580747 | DF16: 5.9909468 | DG16: 6.7905438 | DH16: 4.8371453 | DI16: 4.1628547 | DK16: 29 | DL16: 29 | DM16: 28 | DN16: 28 | DO16: 9 | DQ16: 123 | DR16: =+SUM(Tabla2[[#This Row],[1 gral]:[1 gral]]) -> 3.9587439 | DS16: =+SUM(Tabla2[[#This Row],[1 temm]:[1 temm]]) -> 2.4783653 | DT16: =+SUM(Tabla2[[#This Row],[1 porta]:[1 porta]]) -> 0.241196 | DU16: =+Tabla2[[#This Row],[GRAL]]-(Tabla2[[#This Row],[TEMM14]]+Tabla2[[#This Row],[PORTA15]]) -> 1.2391826
A17: REYES ZARRABAL CRISTOPHER | B17: HIDALGO | C17: VIRGINIA MIRANDA OSORIO | D17: 2090749 | E17: COPPEL CARRANZA LA COLCHONERA | F17: Pachuca de Soto | G17: COPPEL | H17: 0.120598 | I17: 0.16789848 | J17: 0.15622072 | K17: 0.15006953 | L17: 0.16374086 | M17: 0.147431 | N17: 0.094041414 | O17: 0.13456876 | P17: 0.1570793 | Q17: 0.13666662 | R17: 0.15251214 | S17: 0.16144595 | T17: 0.17017768 | U17: 0.087549554 | V17: 0.13996354 | W17: 0.16408049 | X17: 0.14972686 | Y17: 0.14630852 | Z17: 0.15374769 | AA17: 0.16100337 | AB17: 0.085169521 | AC17: 0.14462106 | AD17: 0.1592788 | AE17: 0.15323481 | AF17: 0.13729452 | AG17: 0.1560897 | AH17: 0.16303765 | AI17: 0.086443459 | AJ17: 0.49060674 | AK17: 0.50939326 | AL17: 0 | AM17: 1 | AN17: 1 | AO17: 1 | AP17: 1 | AQ17: 1 | AR17: 0 | AS17: 5 | AT17: 0.96380871 | AU17: 0.77843134 | AV17: 0.73209912 | AW17: 0.71738981 | AX17: 0.81995811 | AY17: 1.2733216 | AZ17: 1.7149913 | BA17: 0.85866808 | BB17: 0.7050863 | BC17: 0.6423955 | BD17: 0.63096301 | BE17: 0.86895144 | BF17: 1.4388218 | BG17: 1.8551139 | BH17: 0.85662081 | BI17: 0.66377922 | BJ17: 0.59563738 | BK17: 0.5529539 | BL17: 0.67660118 | BM17: 1.2297316 | BN17: 1.4246759 | BO17: 0.75420638 | BP17: 0.6071838 | BQ17: 0.56348839 | BR17: 0.5377929 | BS17: 0.70289891 | BT17: 1.307278 | BU17: 1.5271516 | BV17: 1.1016948 | BW17: 0.8983052 | BX17: 0 | BY17: 7 | BZ17: 7 | CA17: 6 | CB17: 6 | CC17: 2 | CD17: 0 | CE17: 28 | CF17: 2.0482154 | CG17: 1.7247612 | CH17: 1.620419 | CI17: 1.5848491 | CJ17: 1.8036571 | CK17: 2.6940741 | CL17: 3.5240241 | CM17: 1.8519049 | CN17: 1.5672519 | CO17: 1.4214576 | CP17: 1.4144382 | CQ17: 1.8993488 | CR17: 3.0478213 | CS17: 3.7977773 | CT17: 1.8532052 | CU17: 1.4916389 | CV17: 1.3410016 | CW17: 1.2522163 | CX17: 1.5069501 | CY17: 2.6204666 | CZ17: 2.9345213 | DA17: 1.6530338 | DB17: 1.3736464 | DC17: 1.2802116 | DD17: 1.2128803 | DE17: 1.5618875 | DF17: 2.7775937 | DG17: 3.1407466 | DH17: 2.1431489 | DI17: 1.8568511 | DK17: 15 | DL17: 15 | DM17: 13 | DN17: 13 | DO17: 4 | DQ17: 60 | DR17: =+SUM(Tabla2[[#This Row],[1 gral]:[1 gral]]) -> 2.0482154 | DS17: =+SUM(Tabla2[[#This Row],[1 temm]:[1 temm]]) -> 0.96380871 | DT17: =+SUM(Tabla2[[#This Row],[1 porta]:[1 porta]]) -> 0.120598 | DU17: =+Tabla2[[#This Row],[GRAL]]-(Tabla2[[#This Row],[TEMM14]]+Tabla2[[#This Row],[PORTA15]]) -> 0.96380871
A18: SANCHEZ MEZA JOB | B18: TOLUCA | C18: ERIK ALEJANDRO GARCIA | D18: 2090826 | E18: COPPEL CANADA GUADALUPE VICTORIA | F18: Ocoyoacac | G18: COPPEL | H18: 0.120598 | I18: 0.16789848 | J18: 0.15622072 | K18: 0.15006953 | L18: 0.16374086 | M18: 0.147431 | N18: 0.094041414 | O18: 0.13456876 | P18: 0.1570793 | Q18: 0.13666662 | R18: 0.15251214 | S18: 0.16144595 | T18: 0.17017768 | U18: 0.087549554 | V18: 0.13996354 | W18: 0.16408049 | X18: 0.14972686 | Y18: 0.14630852 | Z18: 0.15374769 | AA18: 0.16100337 | AB18: 0.085169521 | AC18: 0.14462106 | AD18: 0.1592788 | AE18: 0.15323481 | AF18: 0.13729452 | AG18: 0.1560897 | AH18: 0.16303765 | AI18: 0.086443459 | AJ18: 0 | AK18: 0 | AL18: 0 | AM18: 1 | AN18: 1 | AO18: 1 | AP18: 1 | AQ18: 0 | AR18: 0 | AS18: 4 | AT18: 1.1014957 | AU18: 0.88963582 | AV18: 0.83668471 | AW18: 0.81987406 | AX18: 0.93709498 | AY18: 1.4552246 | AZ18: 1.9599901 | BA18: 0.98133495 | BB18: 0.80581292 | BC18: 0.73416629 | BD18: 0.72110058 | BE18: 0.99308736 | BF18: 1.6443678 | BG18: 2.1201301 | BH18: 1.1421611 | BI18: 0.88503896 | BJ18: 0.79418318 | BK18: 0.73727187 | BL18: 0.90213491 | BM18: 1.6396422 | BN18: 1.8995678 | BO18: 0.87990745 | BP18: 0.7083811 | BQ18: 0.65740312 | BR18: 0.62742505 | BS18: 0.82004872 | BT18: 1.5251577 | BU18: 1.7816769 | BV18: 1.1016948 | BW18: 0.8983052 | BX18: 0 | BY18: 8 | BZ18: 8 | CA18: 8 | CB18: 7 | CC18: 2 | CD18: 0 | CE18: 33 | CF18: 1.7728415 | CG18: 1.5023522 | CH18: 1.4112478 | CI18: 1.3798806 | CJ18: 1.5693833 | CK18: 2.330268 | CL18: 3.0340266 | CM18: 1.6065712 | CN18: 1.3657987 | CO18: 1.237916 | CP18: 1.234163 | CQ18: 1.651077 | CR18: 2.6367293 | CS18: 3.2677448 | CT18: 1.710435 | CU18: 1.3810091 | CV18: 1.2417287 | CW18: 1.1600573 | CX18: 1.3941832 | CY18: 2.4155113 | CZ18: 2.6970753 | DA18: 1.4016317 | DB18: 1.1712518 | DC18: 1.0923821 | DD18: 1.033616 | DE18: 1.3275879 | DF18: 2.3418344 | DG18: 2.6316961 | DH18: 1.6525422 | DI18: 1.3474578 | DK18: 13 | DL18: 13 | DM18: 12 | DN18: 11 | DO18: 3 | DQ18: 52 | DR18: =+SUM(Tabla2[[#This Row],[1 gral]:[1 gral]]) -> 1.7728415 | DS18: =+SUM(Tabla2[[#This Row],[1 temm]:[1 temm]]) -> 1.1014957 | DT18: =+SUM(Tabla2[[#This Row],[1 porta]:[1 porta]]) -> 0.120598 | DU18: =+Tabla2[[#This Row],[GRAL]]-(Tabla2[[#This Row],[TEMM14]]+Tabla2[[#This Row],[PORTA15]]) -> 0.55074783
... A112: SANCHEZ MEZA JOB | B112: TOLUCA | C112: EDSON FERREYRA FFLORES | D112: 209003847 | E112: MEGA PLAZA MIA SANTIAGO T | F112: Toluca de Lerdo | G112: ELEKTRA | H112: 0.120598 | I112: 0.16789848 | J112: 0.15622072 | K112: 0.15006953 | L112: 0.16374086 | M112: 0.147431 | N112: 0.094041414 | O112: 0.13456876 | P112: 0.1570793 | Q112: 0.13666662 | R112: 0.15251214 | S112: 0.16144595 | T112: 0.17017768 | U112: 0.087549554 | V112: 0.13996354 | W112: 0.16408049 | X112: 0.14972686 | Y112: 0.14630852 | Z112: 0.15374769 | AA112: 0.16100337 | AB112: 0.085169521 | AC112: 0.14462106 | AD112: 0.1592788 | AE112: 0.15323481 | AF112: 0.13729452 | AG112: 0.1560897 | AH112: 0.16303765 | AI112: 0.086443459 | AJ112: 0 | AK112: 0 | AL112: 0 | AM112: 1 | AN112: 1 | AO112: 1 | AP112: 1 | AQ112: 0 | AR112: 0 | AS112: 4 | AT112: 0.27537392 | AU112: 0.22240895 | AV112: 0.20917118 | AW112: 0.20496852 | AX112: 0.23427374 | AY112: 0.36380616 | AZ112: 0.48999753 | BA112: 0.24533374 | BB112: 0.20145323 | BC112: 0.18354157 | BD112: 0.18027515 | BE112: 0.24827184 | BF112: 0.41109194 | BG112: 0.53003254 | BH112: 0.28554027 | BI112: 0.22125974 | BJ112: 0.19854579 | BK112: 0.18431797 | BL112: 0.22553373 | BM112: 0.40991054 | BN112: 0.47489196 | BO112: 0.25140213 | BP112: 0.2023946 | BQ112: 0.18782946 | BR112: 0.1792643 | BS112: 0.23429964 | BT112: 0.43575935 | BU112: 0.50905053 | BV112: -0.5508474 | BW112: -0.4491526 | BX112: 0 | BY112: 2 | BZ112: 2 | CA112: 2 | CB112: 2 | CC112: -1 | CD112: 0 | CE112: 7 | CF112: 1.3597806 | CG112: 1.1687388 | CH112: 1.097491 | CI112: 1.0724278 | CJ112: 1.2179727 | CK112: 1.7845587 | CL112: 2.2990303 | CM112: 1.2385706 | CN112: 1.0636188 | CO112: 0.96260369 | CP112: 0.96375029 | CQ112: 1.2786692 | CR112: 2.0200914 | CS112: 2.472696 | CT112: 1.4248947 | CU112: 1.1597493 | CV112: 1.0431829 | CW112: 0.97573938 | CX112: 1.1686495 | CY112: 2.0056008 | CZ112: 2.2221834 | DA112: 1.2759306 | DB112: 1.0700545 | DC112: 0.9984674 | DD112: 0.94398387 | DE112: 1.2104381 | DF112: 2.1239547 | DG112: 2.3771708 | DH112: 0.5508474 | DI112: 0.4491526 | DK112: 10 | DL112: 10 | DM112: 10 | DN112: 10 | DO112: 1 | DQ112: 41 | DR112: =+SUM(Tabla2[[#This Row],[1 gral]:[1 gral]]) -> 1.3597806 | DS112: =+SUM(Tabla2[[#This Row],[1 temm]:[1 temm]]) -> 0.27537392 | DT112: =+SUM(Tabla2[[#This Row],[1 porta]:[1 porta]]) -> 0.120598 | DU112: =+Tabla2[[#This Row],[GRAL]]-(Tabla2[[#This Row],[TEMM14]]+Tabla2[[#This Row],[PORTA15]]) -> 0.96380871

Sheet Altas
A1: Total general | E1: =+SUBTOTAL(9,E3:E108) -> 0 | F1: =+SUBTOTAL(9,F3:F108) -> 0 | G1: =+SUBTOTAL(9,G3:G108) -> 0 | H1: =+SUBTOTAL(9,H3:H108) -> 0 | I1: =+SUBTOTAL(9,I3:I108) -> 0 | J1: =+SUBTOTAL(9,J3:J108) -> 0 | K1: =+SUBTOTAL(9,K3:K108) -> 0 | L1: =+SUBTOTAL(9,L3:L108) -> 0 | ... AI1: =+SUBTOTAL(9,AI3:AI108) -> 0
A2: Total general | B2: NOMBRE PDV | C2: SUPERVISOR | D2: CADENA | E2: 1 | F2: 2 | G2: 3 | H2: 4 | I2: 5 | J2: 6 | K2: 7 | L2: 8 | M2: 9 | N2: 10 | O2: 11 | P2: 12 | Q2: 13 | R2: 14 | S2: 15 | T2: 16 | U2: 17 | V2: 18 | W2: 19 | X2: 20 | Y2: 21 | Z2: 22 | AA2: 23 | AB2: 24 | AC2: 25 | AD2: 26 | AE2: 27 | AF2: 28 | AG2: 29 | AH2: 30 | AI2: 31
A3: 2090171 | B3: COPPEL PLAZA DEL VALLE (194) | C3: DANIEL BENJAMIN MARQUEZ BACA | D3: COPPEL
A4: 2090172 | B4: COPPEL-CANADA OCAMPO (574) | C4: VIRGINIA MIRANDA OSORIO | D4: COPPEL
A5: 2090173 | B5: COPPEL PILARES (TOL) (208) | C5: ERIK ALEJANDRO GARCIA | D5: COPPEL
A6: 2090174 | B6: COPPEL-CANADA JUAREZ (582) | C6: EDGAR RAUL HERNANDEZ CERVANTES | D6: COPPEL
A7: 2090175 | B7: COPPEL - JUAREZ II (64) | C7: EDGAR RAUL HERNANDEZ CERVANTES | D7: COPPEL
A8: 2090176 | B8: COPPEL - 5 DE MAYO (159) | C8: EDGAR RAUL HERNANDEZ CERVANTES | D8: COPPEL
A9: 2090552 | B9: SUBURBIA - METEPEC | C9: EDSON FERREYRA FFLORES | D9: SUBURBIA
A10: 2090559 | B10: SUBURBIA - GRAN PLAZA | C10: EDGAR RAUL HERNANDEZ CERVANTES | D10: SUBURBIA
A11: 2090618 | B11: COPPEL UNIVERSIDAD | C11: VIRGINIA MIRANDA OSORIO | D11: COPPEL
A12: 2090742 | B12: COPPEL SENDERO | C12: ERIK ALEJANDRO GARCIA | D12: COPPEL
A13: 2090749 | B13: COPPEL CARRANZA LA COLCHONERA | C13: VIRGINIA MIRANDA OSORIO | D13: COPPEL
A14: 2090826 | B14: COPPEL CANADA GUADALUPE VICTORIA | C14: ERIK ALEJANDRO GARCIA | D14: COPPEL
... A108: 209003847 | B108: MEGA PLAZA MIA SANTIAGO T | C108: EDSON FERREYRA FFLORES | D108: ELEKTRA
A110: TEMM | E110: =+SUBTOTAL(9,E112:E217) -> 0 | F110: =+SUBTOTAL(9,F112:F217) -> 0 | G110: =+SUBTOTAL(9,G112:G217) -> 0 | H110: =+SUBTOTAL(9,H112:H217) -> 0 | I110: =+SUBTOTAL(9,I112:I217) -> 0 | J110: =+SUBTOTAL(9,J112:J217) -> 0 | K110: =+SUBTOTAL(9,K112:K217) -> 0 | L110: =+SUBTOTAL(9,L112:L217) -> 0 | ... AI110: =+SUBTOTAL(9,AI112:AI217) -> 0
A111: Total general | B111: NOMBRE PDV | C111: SUPERVISOR | D111: CADENA | E111: 1 | F111: 2 | G111: 3 | H111: 4 | I111: 5 | J111: 6 | K111: 7 | L111: 8 | M111: 9 | N111: 10 | O111: 11 | P111: 12 | Q111: 13 | R111: 14 | S111: 15 | T111: 16 | U111: 17 | V111: 18 | W111: 19 | X111: 20 | Y111: 21 | Z111: 22 | AA111: 23 | AB111: 24 | AC111: 25 | AD111: 26 | AE111: 27 | AF111: 28 | AG111: 29 | AH111: 30 | AI111: 31
A112: 2090171 | B112: COPPEL PLAZA DEL VALLE (194) | C112: DANIEL BENJAMIN MARQUEZ BACA | D112: COPPEL
A113: 2090172 | B113: COPPEL-CANADA OCAMPO (574) | C113: VIRGINIA MIRANDA OSORIO | D113: COPPEL
A114: 2090173 | B114: COPPEL PILARES (TOL) (208) | C114: ERIK ALEJANDRO GARCIA | D114: COPPEL
A115: 2090174 | B115: COPPEL-CANADA JUAREZ (582) | C115: EDGAR RAUL HERNANDEZ CERVANTES | D115: COPPEL
A116: 2090175 | B116: COPPEL - JUAREZ II (64) | C116: EDGAR RAUL HERNANDEZ CERVANTES | D116: COPPEL
A117: 2090176 | B117: COPPEL - 5 DE MAYO (159) | C117: EDGAR RAUL HERNANDEZ CERVANTES | D117: COPPEL
A118: 2090552 | B118: SUBURBIA - METEPEC | C118: EDSON FERREYRA FFLORES | D118: SUBURBIA
A119: 2090559 | B119: SUBURBIA - GRAN PLAZA | C119: EDGAR RAUL HERNANDEZ CERVANTES | D119: SUBURBIA
A120: 2090618 | B120: COPPEL UNIVERSIDAD | C120: VIRGINIA MIRANDA OSORIO | D120: COPPEL
A121: 2090742 | B121: COPPEL SENDERO | C121: ERIK ALEJANDRO GARCIA | D121: COPPEL
A122: 2090749 | B122: COPPEL CARRANZA LA COLCHONERA | C122: VIRGINIA MIRANDA OSORIO | D122: COPPEL
A123: 2090826 | B123: COPPEL CANADA GUADALUPE VICTORIA | C123: ERIK ALEJANDRO GARCIA | D123: COPPEL
... A217: 209003847 | B217: MEGA PLAZA MIA SANTIAGO T | C217: EDSON FERREYRA FFLORES | D217: ELEKTRA
A219: PORTABILIDAD | E219: =+SUBTOTAL(9,E221:E326) -> 0 | F219: =+SUBTOTAL(9,F221:F326) -> 0 | G219: =+SUBTOTAL(9,G221:G326) -> 0 | H219: =+SUBTOTAL(9,H221:H326) -> 0 | I219: =+SUBTOTAL(9,I221:I326) -> 0 | J219: =+SUBTOTAL(9,J221:J326) -> 0 | K219: =+SUBTOTAL(9,K221:K326) -> 0 | L219: =+SUBTOTAL(9,L221:L326) -> 0 | ... AI219: =+SUBTOTAL(9,AI221:AI326) -> 0
A220: Total general | B220: NOMBRE PDV | C220: SUPERVISOR | D220: CADENA | E220: 1 | F220: 2 | G220: 3 | H220: 4 | I220: 5 | J220: 6 | K220: 7 | L220: 8 | M220: 9 | N220: 10 | O220: 11 | P220: 12 | Q220: 13 | R220: 14 | S220: 15 | T220: 16 | U220: 17 | V220: 18 | W220: 19 | X220: 20 | Y220: 21 | Z220: 22 | AA220: 23 | AB220: 24 | AC220: 25 | AD220: 26 | AE220: 27 | AF220: 28 | AG220: 29 | AH220: 30 | AI220: 31
A221: 2090171 | B221: COPPEL PLAZA DEL VALLE (194) | C221: DANIEL BENJAMIN MARQUEZ BACA | D221: COPPEL
A222: 2090172 | B222: COPPEL-CANADA OCAMPO (574) | C222: VIRGINIA MIRANDA OSORIO | D222: COPPEL
A223: 2090173 | B223: COPPEL PILARES (TOL) (208) | C223: ERIK ALEJANDRO GARCIA | D223: COPPEL
A224: 2090174 | B224: COPPEL-CANADA JUAREZ (582) | C224: EDGAR RAUL HERNANDEZ CERVANTES | D224: COPPEL
A225: 2090175 | B225: COPPEL - JUAREZ II (64) | C225: EDGAR RAUL HERNANDEZ CERVANTES | D225: COPPEL
A226: 2090176 | B226: COPPEL - 5 DE MAYO (159) | C226: EDGAR RAUL HERNANDEZ CERVANTES | D226: COPPEL
A227: 2090552 | B227: SUBURBIA - METEPEC | C227: EDSON FERREYRA FFLORES | D227: SUBURBIA
A228: 2090559 | B228: SUBURBIA - GRAN PLAZA | C228: EDGAR RAUL HERNANDEZ CERVANTES | D228: SUBURBIA
...

Sheet FieldWy
A1: ID PDV | B1: Nombre PDV | C1: Di Atiende | D1: Nombre Atiende | E1: Di Propietario | F1: DN | G1: Canal | H1: Cadena | I1: Region | J1: Subdirector | K1: Lider Zonal | L1: Supervisor | M1: Usuario | N1: Nombre Usuario | O1: Rol de usuario | P1: EquipoClave | Q1: EquipoClaveIndisegno | R1: Fecha registro | S1: Hora registro | T1: Folio | U1: ID Usuario | V1: Di Patrón | W1: Patrón | X1: Producto | Y1: IMEI | Z1: ICC | AA1: Equipo TEMM | AB1: Monto Recarga | AC1: Costo Equipo | AD1: Rango | AE1: Observaciones

Sheet Resumen dia
E2: VIE | F2: SAB | G2: DOM | H2: LUN | I2: MAR | J2: MIE | K2: JUE | L2: VIE | M2: SAB | N2: DOM | O2: LUN | P2: MAR | Q2: MIE | R2: JUE | S2: VIE | T2: SAB | U2: DOM | V2: LUN | W2: MAR | X2: MIE | Y2: JUE | Z2: VIE | AA2: SAB | AB2: DOM | AC2: LUN | AD2: MAR | AE2: MIE | AF2: JUE | AG2: VIE | AH2: SAB | AI2: DOM
B3: ACUMULADO | C3: ALCANCE AL DIA | D3: GAP | E3: 1 | F3: 2 | G3: 3 | H3: 4 | I3: 5 | J3: 6 | K3: 7 | L3: 8 | M3: 9 | N3: 10 | O3: 11 | P3: 12 | Q3: 13 | R3: 14 | S3: 15 | T3: 16 | U3: 17 | V3: 18 | W3: 19 | X3: 20 | Y3: 21 | Z3: 22 | AA3: 23 | AB3: 24 | AC3: 25 | AD3: 26 | AE3: 27 | AF3: 28 | AG3: 29 | AH3: 30 | AI3: 31
A4: CUOTA TOTAL | B4: =+Cuota!DR5 -> 79.469291 | C4: =IFERROR(B5/B4,0) -> 0 | D4: =+B5-B4 -> -79.469291 | E4: 79.469291 | F4: 68.061585 | G4: 63.917916 | H4: 62.467996 | I4: 70.971153 | J4: 104.33543 | K4: 134.77662 | L4: 72.561193 | M4: 62.237899 | N4: 56.336743 | O4: 56.375968 | P4: 74.870321 | Q4: 118.43395 | R4: 145.18393 | S4: 78.220828 | T4: 63.782484 | U4: 57.376697 | V4: 53.681806 | W4: 64.244915 | X4: 110.01519 | Y4: 121.67809 | Z4: 68.202808 | AA4: 57.350004 | AB4: 53.531711 | AC4: 50.580323 | AD4: 64.777576 | AE4: 113.22175 | AF4: 126.33583 | AG4: 87.567903 | AH4: 76.432097 | AI4: 102.94226
A5: ALTAS TOTAL | B5: =+SUM(E5:AI5) -> 0 | E5: =+Altas!E1 -> 0 | F5: =+Altas!F1 -> 0 | G5: =+Altas!G1 -> 0 | H5: =+Altas!H1 -> 0 | I5: =+Altas!I1 -> 0 | J5: =+Altas!J1 -> 0 | K5: =+Altas!K1 -> 0 | L5: =+Altas!L1 -> 0 | ... AI5: =+Altas!AI1 -> 0
E6: =+E5/E4 -> 0 | F6: =+F5/F4 -> 0 | G6: =+G5/G4 -> 0 | H6: =+H5/H4 -> 0 | I6: =+I5/I4 -> 0 | J6: =+J5/J4 -> 0 | K6: =+K5/K4 -> 0 | L6: =+L5/L4 -> 0 | ... AI6: =+AI5/AI4 -> 0
A7: CUOTA TEMM | B7: =+Cuota!DS5 -> 39.826684 | C7: =IFERROR(B8/B7,0) -> 0 | D7: =+B8-B7 -> -39.826684 | E7: 39.826684 | F7: 32.589462 | G7: 30.639632 | H7: 30.005946 | I7: 34.249317 | J7: 52.545061 | K7: 70.143897 | L7: 35.644803 | M7: 29.548834 | N7: 26.882903 | O7: 26.514143 | P7: 36.223277 | Q7: 59.396122 | R7: 75.789917 | S7: 38.816637 | T7: 30.412028 | U7: 27.304952 | V7: 25.392141 | W7: 30.918472 | X7: 55.484122 | Y7: 63.671648 | Z7: 34.178508 | AA7: 27.772957 | AB7: 25.806813 | AC7: 24.576287 | AD7: 31.98124 | AE7: 58.716339 | AF7: 67.967856 | AG7: 41.132833 | AH7: 33.867167 | AI7: 51.544686
A8: ALTAS TEMM | B8: =+SUM(E8:AI8) -> 0 | E8: =+Altas!E48 -> 0 | F8: =+Altas!F48 -> 0 | G8: =+Altas!G48 -> 0 | H8: =+Altas!H48 -> 0 | I8: =+Altas!I48 -> 0 | J8: =+Altas!J48 -> 0 | K8: =+Altas!K48 -> 0 | L8: =+Altas!L48 -> 0 | ... AI8: =+Altas!AI48 -> 0
E9: =+E8/E7 -> 0 | F9: =+F8/F7 -> 0 | G9: =+G8/G7 -> 0 | H9: =+H8/H7 -> 0 | I9: =+I8/I7 -> 0 | J9: =+J8/J7 -> 0 | K9: =+K8/K7 -> 0 | L9: =+L8/L7 -> 0 | ... AI9: =+AI8/AI7 -> 0
A10: CUOTA PORTA | B10: =+Cuota!DT5 -> 6.63289 | C10: =IFERROR(B11/B10,0) -> 0 | D10: =+B11-B10 -> -6.63289 | E10: 6.63289 | F10: 9.2344162 | G10: 8.5921396 | H10: 8.253824 | I10: 9.0057474 | J10: 8.108705 | K10: 5.1722778 | L10: 7.6704192 | M10: 8.9535202 | N10: 7.7899973 | O10: 8.6931919 | P10: 9.2024193 | Q10: 9.7001276 | R10: 4.9903246 | S10: 7.9779216 | T10: 9.3525881 | U10: 8.5344312 | V10: 8.3395859 | W10: 8.7636181 | X10: 9.1771923 | Y10: 4.8546627 | Z10: 8.2434005 | AA10: 9.0788918 | AB10: 8.7343844 | AC10: 7.8257876 | AD10: 8.8971127 | AE10: 9.2931458 | AF10: 4.9272771 | AG10: 22.56791 | AH10: 23.43209 | AI10: 15.605898
A11: ALTAS PORTA | B11: =+SUM(E11:AI11) -> 0 | E11: =+Altas!E95 -> 0 | F11: =+Altas!F95 -> 0 | G11: =+Altas!G95 -> 0 | H11: =+Altas!H95 -> 0 | I11: =+Altas!I95 -> 0 | J11: =+Altas!J95 -> 0 | K11: =+Altas!K95 -> 0 | L11: =+Altas!L95 -> 0 | ... AI11: =+Altas!AI95 -> 0
E12: =+E11/E10 -> 0 | F12: =+F11/F10 -> 0 | G12: =+G11/G10 -> 0 | H12: =+H11/H10 -> 0 | I12: =+I11/I10 -> 0 | J12: =+J11/J10 -> 0 | K12: =+K11/K10 -> 0 | L12: =+L11/L10 -> 0 | ... AI12: =+AI11/AI10 -> 0
A13: CUOTA PP VOZ | B13: =+Cuota!DU5 -> 33.009717 | C13: =IFERROR(B14/B13,0) -> 0 | D13: =+B14-B13 -> -33.009717 | E13: =+E4-(E7+E10) -> 33.009717 | F13: =+F4-(F7+F10) -> 26.237706 | G13: =+G4-(G7+G10) -> 24.686145 | H13: =+H4-(H7+H10) -> 24.208226 | I13: =+I4-(I7+I10) -> 27.716089 | J13: =+J4-(J7+J10) -> 43.681669 | K13: =+K4-(K7+K10) -> 59.460449 | L13: =+L4-(L7+L10) -> 29.24597 | ... AI13: =+AI4-(AI7+AI10) -> 35.791672
A14: ALTAS PP VOZ | B14: =+SUM(E14:AI14) -> 0 | E14: =+E5-(E8+E11) -> 0 | F14: =+F5-(F8+F11) -> 0 | G14: =+G5-(G8+G11) -> 0 | H14: =+H5-(H8+H11) -> 0 | I14: =+I5-(I8+I11) -> 0 | J14: =+J5-(J8+J11) -> 0 | K14: =+K5-(K8+K11) -> 0 | L14: =+L5-(L8+L11) -> 0 | ... AI14: =+AI5-(AI8+AI11) -> 0
E15: =+E14/E13 -> 0 | F15: =+F14/F13 -> 0 | G15: =+G14/G13 -> 0 | H15: =+H14/H13 -> 0 | I15: =+I14/I13 -> 0 | J15: =+J14/J13 -> 0 | K15: =+K14/K13 -> 0 | L15: =+L14/L13 -> 0 | ... AI15: =+AI14/AI13 -> 0
B16: PROM COB | C16: AUTORIZADO | D16: % | E16: 1 | F16: 2 | G16: 3 | H16: 4 | I16: 5 | J16: 6 | K16: 7 | L16: 8 | M16: 9 | N16: 10 | O16: 11 | P16: 12 | Q16: 13 | R16: 14 | S16: 15 | T16: 16 | U16: 17 | V16: 18 | W16: 19 | X16: 20 | Y16: 21 | Z16: 22 | AA16: 23 | AB16: 24 | AC16: 25 | AD16: 26 | AE16: 27 | AF16: 28 | AG16: 29 | AH16: 30 | AI16: 31
A17: TIENDAS CUB | B17: =+AVERAGE(E17:N17) -> #DIV/0! | C17: 43 | D17: =+B17/C17 -> #DIV/0!
A18: PROM ACTIVOS | B18: =+AVERAGE(E18:N18) -> #DIV/0! | C18: 54 | D18: =+B18/C18 -> #DIV/0!
D19: COBERTURA | E19: =+E17/43 -> 0 | F19: =+F17/43 -> 0 | G19: =+G17/43 -> 0 | H19: =+H17/43 -> 0 | I19: =+I17/43 -> 0 | J19: =+J17/43 -> 0 | K19: =+K17/43 -> 0 | L19: =+L17/43 -> 0 | ... AI19: =+AI17/43 -> 0
D20: ASISTENCIA | E20: =+E18/54 -> 0 | F20: =+F18/54 -> 0 | G20: =+G18/54 -> 0 | H20: =+H18/54 -> 0 | I20: =+I18/54 -> 0 | J20: =+J18/54 -> 0 | K20: =+K18/54 -> 0 | L20: =+L18/54 -> 0 | ... AI20: =+AI18/54 -> 0
D21: SIN CUBRIR | E21: =+$C$17-E17 -> 43 | F21: =+$C$17-F17 -> 43 | G21: =+$C$17-G17 -> 43 | H21: =+$C$17-H17 -> 43 | I21: =+$C$17-I17 -> 43 | J21: =+$C$17-J17 -> 43 | K21: =+$C$17-K17 -> 43 | L21: =+$C$17-L17 -> 43 | ... AI21: =+$C$17-AI17 -> 43

Sheet Seg Diario
AM2: Tiendas en 0
E3: AVANCE AL DIA | F3: 1 | L3: TOTALES | P3: TEMM | T3: PORTABILIDAD | X3: PREPAGO VOZ | AB3: PRODUCTIVIDAD TOTAL | AE3: PRODUCTIVIDAD TEMM | AH3: PRODUCTIVIDAD PORTA | AK3: PRODUCTIVIDAD PREPAGO VOZ | AN3: REGISTROS FIELDWY | AV3: DIAS SIN VENTA
